Workbook

Sheet 能力
B1: Gaining Fate ユニット 初期値一覧
B3: 初期値（CCボーナスなし） | C3: HP | D3: 力 | E3: 魔力 | F3: 技 | G3: 速さ | H3: 幸運 | I3: 守備力 | J3: 魔防力 | K3: 移動力 | L3: 熟練度 | M3: レベル | N3: 転生 | O3: 計（初期値）
B4: ルメンテ | C4: 28 | D4: 9 | E4: 0 | F4: 9 | G4: 7 | H4: 3 | I4: 8 | J4: 0 | K4: 5 | L4: 9 | M4: 6 | N4: 0 | O4: =SUM(C4:L4) -> 78
B5: レジェ | C5: 13 | D5: 4 | E5: 0 | F5: 4 | G5: 5 | H5: 6 | I5: 2 | J5: 0 | K5: 5 | L5: 2 | M5: 1 | N5: 20 | O5: =SUM(C5:L5) -> 41
B6: レガート（パラディン） | C6: 25 | D6: 7 | E6: 1 | F6: 5 | G6: 5 | H6: 5 | I6: 6 | J6: 2 | K6: 7 | L6: 7 | M6: 4 | N6: 20 | O6: =SUM(C6:L6) -> 70
B7: レガート (Uナイト) | C7: 25 | D7: 7 | E7: 1 | F7: 5 | G7: 5 | H7: 5 | I7: 6 | J7: 2 | K7: 7 | L7: 7 | M7: 4 | N7: 20 | O7: =SUM(C7:L7) -> 70
B8: アグリ | C8: 28 | D8: 7 | E8: 0 | F8: 4 | G8: 6 | H8: 4 | I8: 5 | J8: 0 | K8: 5 | L8: 5 | M8: 3 | N8: 20 | O8: =SUM(C8:L8) -> 64
B9: モレンド | C9: 16 | D9: 4 | E9: 0 | F9: 4 | G9: 9 | H9: 6 | I9: 3 | J9: 0 | K9: 6 | L9: 6 | M9: 1 | N9: 0 | O9: =SUM(C9:L9) -> 54
B10: トーン (賢者) | C10: 18 | D10: 0 | E10: 2 | F10: 3 | G10: 4 | H10: 8 | I10: 1 | J10: 5 | K10: 5 | L10: 5 | M10: 1 | N10: 20 | O10: =SUM(C10:L10) -> 51
B11: トーン (学者) | C11: 18 | D11: 0 | E11: 2 | F11: 3 | G11: 4 | H11: 8 | I11: 1 | J11: 5 | K11: 5 | L11: 5 | M11: 1 | N11: 20 | O11: =SUM(C11:L11) -> 51
B12: シュトレンク | C12: 25 | D12: 7 | E12: 0 | F12: 8 | G12: 6 | H12: 4 | I12: 7 | J12: 0 | K12: 5 | L12: 7 | M12: 4 | N12: 20 | O12: =SUM(C12:L12) -> 69
B13: リラ | C13: 18 | D13: 0 | E13: 4 | F13: 7 | G13: 10 | H13: 8 | I13: 2 | J13: 5 | K13: 7 | L13: 7 | M13: 2 | N13: 20 | O13: =SUM(C13:L13) -> 68
B14: ファルコン | C14: 25 | D14: 6 | E14: 0 | F14: 10 | G14: 10 | H14: 5 | I14: 5 | J14: 0 | K14: 7 | L14: 8 | M14: 7 | N14: 0 | O14: =SUM(C14:L14) -> 76
B15: ユーリ（ブレイド） | C15: 27 | D15: 5 | E15: 3 | F15: 8 | G15: 9 | H15: 5 | I15: 4 | J15: 3 | K15: 5 | L15: 7 | M15: 6 | N15: 20 | O15: =SUM(C15:L15) -> 76
... B17: シラヌイ | C17: 24 | D17: 6 | E17: 0 | F17: 11 | G17: 14 | H17: 5 | I17: 4 | J17: 0 | K17: 6 | L17: 7 | M17: 1 | N17: 0 | O17: =SUM(C17:L17) -> 77

Sheet 成長率
B1: Gaining Fate ユニット 成長率一覧
C3: HP | D3: 力 | E3: 魔力 | F3: 技 | G3: 速さ | H3: 幸運 | I3: 守備力 | J3: 魔防力 | K3: 移動力 | L3: 熟練度 | M3: レベル | N3: 転生 | O3: 計
B4: ルメンテ | C4: 0.8 | D4: 0.4 | E4: 0.05 | F4: 0.3 | G4: 0.3 | H4: 0.2 | I4: 0.4 | J4: 0.05 | K4: 0 | L4: 0.4 | M4: 6 | N4: 0 | O4: =SUM(C4:L4) -> 2.9
B5: レジェ | C5: 0.8 | D5: 0.6 | E5: 0.1 | F5: 0.8 | G5: 0.8 | H5: 0.8 | I5: 0.3 | J5: 0.2 | K5: 0 | L5: 0.7 | M5: 1 | N5: 20 | O5: =SUM(C5:L5) -> 5.1
B6: レガート (パラディン) | C6: 0.7 | D6: 0.4 | E6: 0.1 | F6: 0.5 | G6: 0.5 | H6: 0.4 | I6: 0.2 | J6: 0.1 | K6: 0 | L6: 0.4 | M6: 4 | N6: 20 | O6: =SUM(C6:L6) -> 3.3
B7: レガート (Uナイト) | C7: 0.7 | D7: 0.4 | E7: 0.1 | F7: 0.5 | G7: 0.5 | H7: 0.4 | I7: 0.2 | J7: 0.1 | K7: 0 | L7: 0.4 | M7: 4 | N7: 20 | O7: =SUM(C7:L7) -> 3.3
B8: アグリ | C8: 0.9 | D8: 0.5 | E8: 0.05 | F8: 0.5 | G8: 0.4 | H8: 0.4 | I8: 0.3 | J8: 0.05 | K8: 0 | L8: 0.5 | M8: 3 | N8: 20 | O8: =SUM(C8:L8) -> 3.6
B9: モレンド | C9: 0.6 | D9: 0.2 | E9: 0.05 | F9: 0.4 | G9: 0.9 | H9: 0.6 | I9: 0.1 | J9: 0.1 | K9: 0.05 | L9: 0.5 | M9: 1 | N9: 0 | O9: =SUM(C9:L9) -> 3.5
B10: トーン (賢者) | C10: 0.6 | D10: 0 | E10: 0.2 | F10: 0.4 | G10: 0.4 | H10: 0.7 | I10: 0.1 | J10: 0.4 | K10: 0 | L10: 0.7 | M10: 1 | N10: 20 | O10: =SUM(C10:L10) -> 3.5
B11: トーン (学者) | C11: 0.6 | D11: 0 | E11: 0.2 | F11: 0.4 | G11: 0.4 | H11: 0.7 | I11: 0.1 | J11: 0.4 | K11: 0 | L11: 0.7 | M11: 1 | N11: 20 | O11: =SUM(C11:L11) -> 3.5
B12: シュトレンク | C12: 0.6 | D12: 0.5 | E12: 0.05 | F12: 0.7 | G12: 0.4 | H12: 0.4 | I12: 0.4 | J12: 0.1 | K12: 0 | L12: 0.8 | M12: 4 | N12: 20 | O12: =SUM(C12:L12) -> 3.95
B13: リラ | C13: 0.5 | D13: 0 | E13: 0.4 | F13: 0.7 | G13: 0.8 | H13: 0.7 | I13: 0.2 | J13: 0.4 | K13: 0 | L13: 0.7 | M13: 2 | N13: 20 | O13: =SUM(C13:L13) -> 4.4
B14: ファルコン | C14: 0.5 | D14: 0.2 | E14: 0.05 | F14: 0.5 | G14: 0.2 | H14: 0.2 | I14: 0.1 | J14: 0.05 | K14: 0 | L14: 0.7 | M14: 7 | N14: 0 | O14: =SUM(C14:L14) -> 2.5
B15: ユーリ（ブレイド） | C15: 0.7 | D15: 0.2 | E15: 0.2 | F15: 0.4 | G15: 0.4 | H15: 0.5 | I15: 0.2 | J15: 0.2 | K15: 0 | L15: 0.8 | M15: 6 | N15: 20 | O15: =SUM(C15:L15) -> 3.6
... B19: ソナタ | C19: 0.9 | D19: 0.2 | E19: 0.05 | F19: 0.5 | G19: 0.4 | H19: 0.1 | I19: 0.4 | J19: 0.05 | K19: 0 | L19: 0.7 | M19: 11 | N19: 0 | O19: =SUM(C19:L19) -> 3.3

Sheet 転生後成長率
B1: Gaining Fate ユニット 転生後成長率一覧
C3: HP | D3: 力 | E3: 魔力 | F3: 技 | G3: 速さ | H3: 幸運 | I3: 守備力 | J3: 魔防力 | K3: 移動力 | L3: 熟練度 | M3: レベル | N3: 転生 | O3: 計
B4: ルメンテ | C4: 0.8 | D4: 0.3 | E4: 0 | F4: 0.3 | G4: 0.3 | H4: 0.2 | I4: 0.3 | J4: 0.05 | K4: 0 | L4: 0.6 | M4: 6 | N4: 0 | O4: =SUM(C4:L4) -> 2.85
B5: レジェ | C5: 1.2 | D5: 0.5 | E5: 0 | F5: 0.8 | G5: 0.8 | H5: 0.8 | I5: 0.3 | J5: 0.07 | K5: 0 | L5: 0.8 | M5: 1 | N5: 20 | O5: =SUM(C5:L5) -> 5.27
B6: レガート | C6: 0.7 | D6: 0.4 | E6: 0.1 | F6: 0.5 | G6: 0.5 | H6: 0.4 | I6: 0.2 | J6: 0.1 | K6: 0 | L6: 0.4 | M6: 4 | N6: 20 | O6: =SUM(C6:L6) -> 3.3
B7: レガート (Uナイト) | C7: 0.7 | D7: 0.4 | E7: 0.1 | F7: 0.5 | G7: 0.5 | H7: 0.4 | I7: 0.2 | J7: 0.1 | K7: 0 | L7: 0.4 | M7: 4 | N7: 20 | O7: =SUM(C7:L7) -> 3.3
B8: アグリ | C8: 0.9 | D8: 0.5 | E8: 0 | F8: 0.5 | G8: 0.4 | H8: 0.4 | I8: 0.3 | J8: 0 | K8: 0 | L8: 0.6 | M8: 3 | N8: 20 | O8: =SUM(C8:L8) -> 3.6
B9: モレンド | C9: 0.6 | D9: 0.2 | E9: 0 | F9: 0.4 | G9: 0.9 | H9: 0.6 | I9: 0.1 | J9: 0.05 | K9: 0.05 | L9: 0.6 | M9: 1 | N9: 0 | O9: =SUM(C9:L9) -> 3.5
B10: トーン (賢者) | C10: 0.6 | D10: 0 | E10: 0.2 | F10: 0.4 | G10: 0.4 | H10: 0.7 | I10: 0.1 | J10: 0.3 | K10: 0 | L10: 0.8 | M10: 1 | N10: 20 | O10: =SUM(C10:L10) -> 3.5
B11: トーン (学者) | C11: 0.6 | D11: 0 | E11: 0.2 | F11: 0.4 | G11: 0.4 | H11: 0.7 | I11: 0.1 | J11: 0.3 | K11: 0 | L11: 0.8 | M11: 1 | N11: 20 | O11: =SUM(C11:L11) -> 3.5
B12: シュトレンク | C12: 0.6 | D12: 0.5 | E12: 0 | F12: 0.7 | G12: 0.4 | H12: 0.4 | I12: 0.4 | J12: 0.05 | K12: 0 | L12: 0.8 | M12: 4 | N12: 20 | O12: =SUM(C12:L12) -> 3.85
B13: リラ | C13: 0.5 | D13: 0 | E13: 0.4 | F13: 0.7 | G13: 0.8 | H13: 0.7 | I13: 0.2 | J13: 0.3 | K13: 0 | L13: 0.7 | M13: 2 | N13: 20 | O13: =SUM(C13:L13) -> 4.3
B14: ファルコン | C14: 0.5 | D14: 0.2 | E14: 0 | F14: 0.5 | G14: 0.2 | H14: 0.2 | I14: 0.1 | J14: 0.05 | K14: 0 | L14: 0.7 | M14: 7 | N14: 0 | O14: =SUM(C14:L14) -> 2.45
B15: ユーリ（ブレイド） | C15: 0.7 | D15: 0.4 | E15: 0.2 | F15: 0.4 | G15: 0.4 | H15: 0.5 | I15: 0.4 | J15: 0.2 | K15: 0 | L15: 0.5 | M15: 6 | N15: 20 | O15: =SUM(C15:L15) -> 3.7
... B17: シラヌイ | C17: 0.7 | D17: 0.3 | E17: 0 | F17: 0.6 | G17: 0.7 | H17: 0.4 | I17: 0.2 | J17: 0 | K17: 0 | L17: 0.7 | M17: 1 | N17: 20 | O17: =SUM(C17:L17) -> 3.6

Sheet 掲載用
B2: Lv.6 | C2: HP | D2: 力 | E2: 魔力 | F2: 技 | G2: 速さ | H2: 幸運 | I2: 守備力 | J2: 魔防力 | K2: 移動力 | L2: 熟練度 | M2: 計（初期値）
B3: 能力 | C3: 25 | D3: 6 | E3: 0 | F3: 10 | G3: 10 | H3: 5 | I3: 5 | J3: 0 | K3: 6 | L3: 8 | M3: =SUM(C3:L3) -> 75
B4: 成長率 | C4: 0.5 | D4: 0.2 | E4: 0 | F4: 0.5 | G4: 0.2 | H4: 0.2 | I4: 0.1 | J4: 0.05 | K4: 0 | L4: 0.7 | M4: =SUM(C4:L4) -> 2.45
B5: 期待値 | C5: 38.5 | D5: 11.6 | E5: 0 | F5: 24.5 | G5: 16.6 | H5: 9.6 | I5: 8.3 | J5: 4.15 | K5: 7 | L5: 26.1 | M5: =SUM(C5:L5) -> 146.35
B8: Lv.2 | C8: HP | D8: 力 | E8: 魔力 | F8: 技 | G8: 速さ | H8: 幸運 | I8: 守備力 | J8: 魔防力 | K8: 移動力 | L8: 熟練度 | M8: 計（初期値）
B9: 能力 | C9: 18 | D9: 0 | E9: 4 | F9: 7 | G9: 10 | H9: 8 | I9: 2 | J9: 6 | K9: 5 | L9: 7 | M9: =SUM(C9:L9) -> 67
B10: 転生ブースト | C10: 0 | D10: 0 | E10: 2 | F10: 3 | G10: 5 | H10: 3 | I10: 1 | J10: 2 | K10: 1 | L10: 2 | M10: =SUM(C10:L10) -> 19
B11: 成長率 | C11: 0.5 | D11: 0 | E11: 0.4 | F11: 0.7 | G11: 0.8 | H11: 0.7 | I11: 0.2 | J11: 0.3 | K11: 0 | L11: 0.7 | M11: =SUM(C11:L11) -> 4.3
B12: 転生後成長率 | C12: 0.5 | D12: 0 | E12: 0.4 | F12: 0.7 | G12: 0.8 | H12: 0.7 | I12: 0.2 | J12: 0.3 | K12: 0 | L12: 0.7 | M12: =SUM(C12:L12) -> 4.3
B13: 期待値 | C13: 32 | D13: 0 | E13: 17.2 | F13: 29.6 | G13: 37.4 | H13: 30.6 | I13: 8.6 | J13: 16.4 | K13: 6 | L13: 28.6 | M13: =SUM(C13:L13) -> 206.4
B18: Lv.6 | C18: HP | D18: 力 | E18: 魔力 | F18: 技 | G18: 速さ | H18: 幸運 | I18: 守備力 | J18: 魔防力 | K18: 移動力 | L18: 熟練度 | M18: 計（初期値）
B19: 能力 | C19: 27 | D19: 4 | E19: 3 | F19: 8 | G19: 9 | H19: 5 | I19: 4 | J19: 3 | K19: 4 | L19: 7 | M19: =SUM(C19:L19) -> 74
B20: 転生ブースト(メイジ) | C20: 3 | D20: 0 | E20: 3 | F20: 1 | G20: 3 | H20: 1 | I20: 0 | J20: 3 | K20: 0 | L20: 0 | M20: =SUM(C20:L20) -> 14
B21: 転生ブースト(ブレイド) | C21: 3 | D21: 3 | E21: 0 | F21: 3 | G21: 1 | H21: 1 | I21: 3 | J21: 0 | K21: 0 | L21: 0 | M21: =SUM(C21:L21) -> 14
B22: 成長率 | C22: 0.7 | D22: 0.2 | E22: 0.2 | F22: 0.4 | G22: 0.4 | H22: 0.5 | I22: 0.3 | J22: 0.3 | K22: 0 | L22: 0.5 | M22: =SUM(C22:L22) -> 3.5
B23: 転生後成長率 | C23: 0.7 | D23: 0.2 | E23: 0.2 | F23: 0.4 | G23: 0.4 | H23: 0.5 | I23: 0.3 | J23: 0.3 | K23: 0 | L23: 0.5 | M23: =SUM(C23:L23) -> 3.5
B24: 期待値 | C24: 53.8 | D24: 16.2 | E24: 14.2 | F24: 31.4 | G24: 33.8 | H24: 23 | I24: 13.8 | J24: 9.8 | K24: 4 | L24: 24 | M24: =SUM(C24:L24) -> 224
B28: Lv6 | C28: HP | D28: 力 | E28: 魔力 | F28: 技 | G28: 速さ | H28: 幸運 | I28: 守備力 | J28: 魔防力 | K28: 移動力 | L28: 熟練度 | M28: 計（初期値）
B29: 能力 | C29: 27 | D29: 4 | E29: 3 | F29: 8 | G29: 9 | H29: 5 | I29: 4 | J29: 3 | K29: 4 | L29: 7 | M29: =SUM(C29:L29) -> 74
B30: 転生ブースト(メイジ) | C30: 3 | D30: 3 | E30: 1 | F30: 3 | G30: 1 | H30: 1 | I30: 3 | J30: 0 | K30: 0 | L30: 2 | M30: =SUM(C30:L30) -> 17
B31: 転生ブースト(ブレイド) | C31: 3 | D31: 1 | E31: 3 | F31: 1 | G31: 3 | H31: 1 | I31: 0 | J31: 3 | K31: 0 | L31: 2 | M31: =SUM(C31:L31) -> 17
B32: 成長率 | C32: 0.7 | D32: 0.3 | E32: 0.3 | F32: 0.4 | G32: 0.4 | H32: 0.5 | I32: 0.3 | J32: 0.3 | K32: 0 | L32: 0.5 | M32: =SUM(C32:L32) -> 3.7
B33: 転生後成長率 (メイジ) | C33: 0.7 | D33: 0.4 | E33: 0.2 | F33: 0.4 | G33: 0.4 | H33: 0.5 | I33: 0.4 | J33: 0.2 | K33: 0 | L33: 0.5 | M33: =SUM(C33:L33) -> 3.7
B34: 転生後成長率(ブレイド) | C34: 0.7 | D34: 0.2 | E34: 0.4 | F34: 0.4 | G34: 0.4 | H34: 0.5 | I34: 0.2 | J34: 0.4 | K34: 0 | L34: 0.5 | M34: =SUM(C34:L34) -> 3.7
B35: 期待値 (メイジ) | C35: 46.8 | D35: 15.7 | E35: 9.7 | F35: 20.6 | G35: 19.6 | H35: 18 | I35: 15.7 | J35: 8.7 | K35: 4 | L35: 21 | M35: =SUM(C35:L35) -> 179.8
B36: 期待値 (ブレイド) | C36: 46.8 | D36: 10.7 | E36: 14.7 | F36: 18.6 | G36: 21.6 | H36: 18 | I36: 9.7 | J36: 14.7 | K36: 4 | L36: 21 | M36: =SUM(C36:L36) -> 179.8
B38: Lv.7 | C38: HP | D38: 力 | E38: 魔力 | F38: 技 | G38: 速さ | H38: 幸運 | I38: 守備力 | J38: 魔防力 | K38: 移動力 | L38: 熟練度 | M38: 計（初期値）
B39: 能力 | C39: 25 | D39: 6 | E39: 0 | F39: 10 | G39: 10 | H39: 5 | I39: 5 | J39: 0 | K39: 6 | L39: 8 | M39: =SUM(C39:L39) -> 75
B40: 転生ブースト | C40: 0 | D40: 0 | E40: 0 | F40: 0 | G40: 0 | H40: 0 | I40: 0 | J40: 0 | K40: 0 | L40: 0 | M40: =SUM(C40:L40) -> 0
B41: 成長率 | C41: 0.5 | D41: 0.2 | E41: 0 | F41: 0.7 | G41: 0.3 | H41: 0.3 | I41: 0.2 | J41: 0 | K41: 0 | L41: 0.7 | M41: =SUM(C41:L41) -> 2.9
B42: 転生後成長率 | C42: 0.5 | D42: 0.2 | E42: 0 | F42: 0.7 | G42: 0.3 | H42: 0.3 | I42: 0.2 | J42: 0 | K42: 0 | L42: 0.7 | M42: =SUM(C42:L42) -> 2.9
B43: 期待値 | C43: 36.5 | D43: 10.6 | E43: 0 | F43: 26.1 | G43: 16.9 | H43: 11.9 | I43: 9.6 | J43: 0 | K43: 6 | L43: 24.1 | M43: =SUM(C43:L43) -> 141.7
B46: Lv.1 | C46: HP | D46: 力 | E46: 魔力 | F46: 技 | G46: 速さ | H46: 幸運 | I46: 守備力 | J46: 魔防力 | K46: 移動力 | L46: 熟練度 | M46: 計（初期値）
B47: 能力 | C47: 16 | D47: 4 | E47: 0 | F47: 4 | G47: 9 | H47: 6 | I47: 3 | J47: 0 | K47: 5 | L47: 6 | M47: =SUM(C47:L47) -> 53
B48: 成長率 | C48: 0.6 | D48: 0.3 | E48: 0 | F48: 0.6 | G48: 0.9 | H48: 0.6 | I48: 0.1 | J48: 0.05 | K48: 0.05 | L48: 0.8 | M48: =SUM(C48:L48) -> 4
B49: 期待値 | C49: 27.4 | D49: 9.7 | E49: 0 | F49: 15.4 | G49: 26.1 | H49: 17.4 | I49: 4.9 | J49: 0.95 | K49: 5.95 | L49: 21.2 | M49: =SUM(C49:L49) -> 129

Sheet 転生後能力
B1: Gaining Fate ユニット 転生後能力一覧
C3: HP | D3: 力 | E3: 魔力 | F3: 技 | G3: 速さ | H3: 幸運 | I3: 守備力 | J3: 魔防力 | K3: 移動力 | L3: 熟練度 | M3: レベル | N3: 転生 | O3: 計（初期値）
B4: ルメンテ | C4: 0 | D4: 0 | E4: 0 | F4: 0 | G4: 0 | H4: 0 | I4: 0 | J4: 0 | K4: 0 | L4: 0 | M4: 6 | N4: 0 | O4: =SUM(C4:L4) -> 0
B5: レジェ | C5: 2 | D5: 2 | E5: 0 | F5: 2 | G5: 2 | H5: 2 | I5: 2 | J5: 2 | K5: 0 | L5: 2 | M5: 1 | N5: 20 | O5: =SUM(C5:L5) -> 16
B6: レガート（パラディン） | C6: 2 | D6: 2 | E6: 0 | F6: 2 | G6: 2 | H6: 1 | I6: 2 | J6: 2 | K6: 1 | L6: 2 | M6: 4 | N6: 20 | O6: =SUM(C6:L6) -> 16
B7: レガート (Uナイト) | C7: 2 | D7: 1 | E7: 0 | F7: 2 | G7: 0 | H7: 1 | I7: 3 | J7: 2 | K7: 1 | L7: 4 | M7: 4 | N7: 20 | O7: =SUM(C7:L7) -> 16
B8: アグリ | C8: 7 | D8: 3 | E8: 0 | F8: 2 | G8: 2 | H8: 1 | I8: 1 | J8: 0 | K8: 0 | L8: 0 | M8: 3 | N8: 20 | O8: =SUM(C8:L8) -> 16
B9: モレンド | C9: 0 | D9: 0 | E9: 0 | F9: 0 | G9: 0 | H9: 0 | I9: 0 | J9: 0 | K9: 0 | L9: 0 | M9: 1 | N9: 0 | O9: =SUM(C9:L9) -> 0
B10: トーン (賢者) | C10: 2 | D10: 0 | E10: 3 | F10: 2 | G10: 0 | H10: 3 | I10: 1 | J10: 2 | K10: 0 | L10: 3 | M10: 1 | N10: 20 | O10: =SUM(C10:L10) -> 16
B11: トーン (学者) | C11: 3 | D11: 0 | E11: 1 | F11: 2 | G11: 0 | H11: 0 | I11: 0 | J11: 5 | K11: 0 | L11: 5 | M11: 1 | N11: 20 | O11: =SUM(C11:L11) -> 16
B12: シュトレンク | C12: 2 | D12: 2 | E12: 0 | F12: 2 | G12: 0 | H12: 2 | I12: 3 | J12: 3 | K12: 0 | L12: 2 | M12: 4 | N12: 20 | O12: =SUM(C12:L12) -> 16
B13: リラ | C13: 1 | D13: 0 | E13: 2 | F13: 3 | G13: 3 | H13: 3 | I13: 1 | J13: 2 | K13: 1 | L13: 0 | M13: 2 | N13: 20 | O13: =SUM(C13:L13) -> 16
B14: ファルコン | C14: 2 | D14: 1 | E14: 0 | F14: 5 | G14: 2 | H14: 0 | I14: 1 | J14: 2 | K14: 1 | L14: 2 | M14: 7 | N14: 0 | O14: =SUM(C14:L14) -> 16
B15: ユーリ（ブレイド） | C15: 3 | D15: 3 | E15: 1 | F15: 1 | G15: 2 | H15: 1 | I15: 3 | J15: 0 | K15: 0 | L15: 2 | M15: 6 | N15: 20 | O15: =SUM(C15:L15) -> 16
... B17: シラヌイ | C17: 0 | D17: 0 | E17: 0 | F17: 0 | G17: 0 | H17: 0 | I17: 0 | J17: 0 | K17: 0 | L17: 0 | M17: 1 | N17: 0 | O17: =SUM(C17:L17) -> 0

Sheet 期待値
B1: Gaining Fate ユニット 期待値一覧
C3: HP | D3: 力 | E3: 魔力 | F3: 技 | G3: 速さ | H3: 幸運 | I3: 守備力 | J3: 魔防力 | K3: 移動力 | L3: 熟練度 | M3: レベル | N3: 転生 | O3: 計（期待値）
B4: ルメンテ | C4: =能力!C4 + (成長率!C4 * (15 - 能力!$M4)) + 転生後能力!C4 + (転生後成長率!C4 * 15) -> 47.2 | D4: =能力!D4 + (成長率!D4 * (15 - 能力!$M4)) + 転生後能力!D4 + (転生後成長率!D4 * 15) -> 17.1 | E4: =能力!E4 + (成長率!E4 * (15 - 能力!$M4)) + 転生後能力!E4 + (転生後成長率!E4 * 15) -> 0.45 | F4: =能力!F4 + (成長率!F4 * (15 - 能力!$M4)) + 転生後能力!F4 + (転生後成長率!F4 * 15) -> 16.2 | G4: =能力!G4 + (成長率!G4 * (15 - 能力!$M4)) + 転生後能力!G4 + (転生後成長率!G4 * 15) -> 14.2 | H4: =能力!H4 + (成長率!H4 * (15 - 能力!$M4)) + 転生後能力!H4 + (転生後成長率!H4 * 15) -> 7.8 | I4: =能力!I4 + (成長率!I4 * (15 - 能力!$M4)) + 転生後能力!I4 + (転生後成長率!I4 * 15) -> 16.1 | J4: =能力!J4 + (成長率!J4 * (15 - 能力!$M4)) + 転生後能力!J4 + (転生後成長率!J4 * 15) -> 1.2 | ... L4: =能力!L4 + (成長率!L4 * (15 - 能力!$M4)) + 転生後能力!L4 + (転生後成長率!L4 * 15) -> 21.6 | M4: 6 | N4: 0 | O4: =SUM(C4:L4) -> 146.85
B5: レジェ | C5: =能力!C5 + (成長率!C5 * (15 - 能力!$M5)) + 転生後能力!C5 + (転生後成長率!C5 * 15) -> 44.2 | D5: =能力!D5 + (成長率!D5 * (15 - 能力!$M5)) + 転生後能力!D5 + (転生後成長率!D5 * 15) -> 21.9 | E5: =能力!E5 + (成長率!E5 * (15 - 能力!$M5)) + 転生後能力!E5 + (転生後成長率!E5 * 15) -> 1.4 | F5: =能力!F5 + (成長率!F5 * (15 - 能力!$M5)) + 転生後能力!F5 + (転生後成長率!F5 * 15) -> 29.2 | G5: =能力!G5 + (成長率!G5 * (15 - 能力!$M5)) + 転生後能力!G5 + (転生後成長率!G5 * 15) -> 30.2 | H5: =能力!H5 + (成長率!H5 * (15 - 能力!$M5)) + 転生後能力!H5 + (転生後成長率!H5 * 15) -> 31.2 | I5: =能力!I5 + (成長率!I5 * (15 - 能力!$M5)) + 転生後能力!I5 + (転生後成長率!I5 * 15) -> 12.7 | J5: =能力!J5 + (成長率!J5 * (15 - 能力!$M5)) + 転生後能力!J5 + (転生後成長率!J5 * 15) -> 5.85 | ... L5: =能力!L5 + (成長率!L5 * (15 - 能力!$M5)) + 転生後能力!L5 + (転生後成長率!L5 * 15) -> 25.8 | M5: 1 | N5: 20 | O5: =SUM(C5:L5) -> 207.45
B6: レガート（パラディン） | C6: =能力!C6 + (成長率!C6 * (15 - 能力!$M6)) + 転生後能力!C6 + (転生後成長率!C6 * 15) -> 45.2 | D6: =能力!D6 + (成長率!D6 * (15 - 能力!$M6)) + 転生後能力!D6 + (転生後成長率!D6 * 15) -> 19.4 | E6: =能力!E6 + (成長率!E6 * (15 - 能力!$M6)) + 転生後能力!E6 + (転生後成長率!E6 * 15) -> 3.6 | F6: =能力!F6 + (成長率!F6 * (15 - 能力!$M6)) + 転生後能力!F6 + (転生後成長率!F6 * 15) -> 20 | G6: =能力!G6 + (成長率!G6 * (15 - 能力!$M6)) + 転生後能力!G6 + (転生後成長率!G6 * 15) -> 20 | H6: =能力!H6 + (成長率!H6 * (15 - 能力!$M6)) + 転生後能力!H6 + (転生後成長率!H6 * 15) -> 16.4 | I6: =能力!I6 + (成長率!I6 * (15 - 能力!$M6)) + 転生後能力!I6 + (転生後成長率!I6 * 15) -> 13.2 | J6: =能力!J6 + (成長率!J6 * (15 - 能力!$M6)) + 転生後能力!J6 + (転生後成長率!J6 * 15) -> 6.6 | ... L6: =能力!L6 + (成長率!L6 * (15 - 能力!$M6)) + 転生後能力!L6 + (転生後成長率!L6 * 15) -> 19.4 | M6: 4 | N6: 20 | O6: =SUM(C6:L6) -> 171.8
B7: レガート (Uナイト) | C7: =能力!C7 + (成長率!C7 * (15 - 能力!$M7)) + 転生後能力!C7 + (転生後成長率!C7 * 15) -> 45.2 | D7: =能力!D7 + (成長率!D7 * (15 - 能力!$M7)) + 転生後能力!D7 + (転生後成長率!D7 * 15) -> 18.4 | E7: =能力!E7 + (成長率!E7 * (15 - 能力!$M7)) + 転生後能力!E7 + (転生後成長率!E7 * 15) -> 3.6 | F7: =能力!F7 + (成長率!F7 * (15 - 能力!$M7)) + 転生後能力!F7 + (転生後成長率!F7 * 15) -> 20 | G7: =能力!G7 + (成長率!G7 * (15 - 能力!$M7)) + 転生後能力!G7 + (転生後成長率!G7 * 15) -> 18 | H7: =能力!H7 + (成長率!H7 * (15 - 能力!$M7)) + 転生後能力!H7 + (転生後成長率!H7 * 15) -> 16.4 | I7: =能力!I7 + (成長率!I7 * (15 - 能力!$M7)) + 転生後能力!I7 + (転生後成長率!I7 * 15) -> 14.2 | J7: =能力!J7 + (成長率!J7 * (15 - 能力!$M7)) + 転生後能力!J7 + (転生後成長率!J7 * 15) -> 6.6 | ... L7: =能力!L7 + (成長率!L7 * (15 - 能力!$M7)) + 転生後能力!L7 + (転生後成長率!L7 * 15) -> 21.4 | M7: 4 | N7: 20 | O7: =SUM(C7:L7) -> 171.8
B8: アグリ | C8: =能力!C8 + (成長率!C8 * (15 - 能力!$M8)) + 転生後能力!C8 + (転生後成長率!C8 * 15) -> 59.3 | D8: =能力!D8 + (成長率!D8 * (15 - 能力!$M8)) + 転生後能力!D8 + (転生後成長率!D8 * 15) -> 23.5 | E8: =能力!E8 + (成長率!E8 * (15 - 能力!$M8)) + 転生後能力!E8 + (転生後成長率!E8 * 15) -> 0.6 | F8: =能力!F8 + (成長率!F8 * (15 - 能力!$M8)) + 転生後能力!F8 + (転生後成長率!F8 * 15) -> 19.5 | G8: =能力!G8 + (成長率!G8 * (15 - 能力!$M8)) + 転生後能力!G8 + (転生後成長率!G8 * 15) -> 18.8 | H8: =能力!H8 + (成長率!H8 * (15 - 能力!$M8)) + 転生後能力!H8 + (転生後成長率!H8 * 15) -> 15.8 | I8: =能力!I8 + (成長率!I8 * (15 - 能力!$M8)) + 転生後能力!I8 + (転生後成長率!I8 * 15) -> 14.1 | J8: =能力!J8 + (成長率!J8 * (15 - 能力!$M8)) + 転生後能力!J8 + (転生後成長率!J8 * 15) -> 0.6 | ... L8: =能力!L8 + (成長率!L8 * (15 - 能力!$M8)) + 転生後能力!L8 + (転生後成長率!L8 * 15) -> 20 | M8: 3 | N8: 20 | O8: =SUM(C8:L8) -> 177.2
B9: モレンド | C9: =能力!C9 + (成長率!C9 * (15 - 能力!$M9)) + 転生後能力!C9 + (転生後成長率!C9 * 15) -> 33.4 | D9: =能力!D9 + (成長率!D9 * (15 - 能力!$M9)) + 転生後能力!D9 + (転生後成長率!D9 * 15) -> 9.8 | E9: =能力!E9 + (成長率!E9 * (15 - 能力!$M9)) + 転生後能力!E9 + (転生後成長率!E9 * 15) -> 0.7 | F9: =能力!F9 + (成長率!F9 * (15 - 能力!$M9)) + 転生後能力!F9 + (転生後成長率!F9 * 15) -> 15.6 | G9: =能力!G9 + (成長率!G9 * (15 - 能力!$M9)) + 転生後能力!G9 + (転生後成長率!G9 * 15) -> 35.1 | H9: =能力!H9 + (成長率!H9 * (15 - 能力!$M9)) + 転生後能力!H9 + (転生後成長率!H9 * 15) -> 23.4 | I9: =能力!I9 + (成長率!I9 * (15 - 能力!$M9)) + 転生後能力!I9 + (転生後成長率!I9 * 15) -> 5.9 | J9: =能力!J9 + (成長率!J9 * (15 - 能力!$M9)) + 転生後能力!J9 + (転生後成長率!J9 * 15) -> 2.15 | ... L9: =能力!L9 + (成長率!L9 * (15 - 能力!$M9)) + 転生後能力!L9 + (転生後成長率!L9 * 15) -> 22 | M9: 1 | N9: 0 | O9: =SUM(C9:L9) -> 155.5
B10: トーン (賢者) | C10: =能力!C10 + (成長率!C10 * (15 - 能力!$M10)) + 転生後能力!C10 + (転生後成長率!C10 * 15) -> 37.4 | D10: =能力!D10 + (成長率!D10 * (15 - 能力!$M10)) + 転生後能力!D10 + (転生後成長率!D10 * 15) -> 0 | E10: =能力!E10 + (成長率!E10 * (15 - 能力!$M10)) + 転生後能力!E10 + (転生後成長率!E10 * 15) -> 10.8 | F10: =能力!F10 + (成長率!F10 * (15 - 能力!$M10)) + 転生後能力!F10 + (転生後成長率!F10 * 15) -> 16.6 | G10: =能力!G10 + (成長率!G10 * (15 - 能力!$M10)) + 転生後能力!G10 + (転生後成長率!G10 * 15) -> 15.6 | H10: =能力!H10 + (成長率!H10 * (15 - 能力!$M10)) + 転生後能力!H10 + (転生後成長率!H10 * 15) -> 31.3 | I10: =能力!I10 + (成長率!I10 * (15 - 能力!$M10)) + 転生後能力!I10 + (転生後成長率!I10 * 15) -> 4.9 | J10: =能力!J10 + (成長率!J10 * (15 - 能力!$M10)) + 転生後能力!J10 + (転生後成長率!J10 * 15) -> 17.1 | ... L10: =能力!L10 + (成長率!L10 * (15 - 能力!$M10)) + 転生後能力!L10 + (転生後成長率!L10 * 15) -> 29.8 | M10: 1 | N10: 20 | O10: =SUM(C10:L10) -> 168.5
B11: トーン (学者) | C11: =能力!C11 + (成長率!C11 * (15 - 能力!$M11)) + 転生後能力!C11 + (転生後成長率!C11 * 15) -> 38.4 | D11: =能力!D11 + (成長率!D11 * (15 - 能力!$M11)) + 転生後能力!D11 + (転生後成長率!D11 * 15) -> 0 | E11: =能力!E11 + (成長率!E11 * (15 - 能力!$M11)) + 転生後能力!E11 + (転生後成長率!E11 * 15) -> 8.8 | F11: =能力!F11 + (成長率!F11 * (15 - 能力!$M11)) + 転生後能力!F11 + (転生後成長率!F11 * 15) -> 16.6 | G11: =能力!G11 + (成長率!G11 * (15 - 能力!$M11)) + 転生後能力!G11 + (転生後成長率!G11 * 15) -> 15.6 | H11: =能力!H11 + (成長率!H11 * (15 - 能力!$M11)) + 転生後能力!H11 + (転生後成長率!H11 * 15) -> 28.3 | I11: =能力!I11 + (成長率!I11 * (15 - 能力!$M11)) + 転生後能力!I11 + (転生後成長率!I11 * 15) -> 3.9 | J11: =能力!J11 + (成長率!J11 * (15 - 能力!$M11)) + 転生後能力!J11 + (転生後成長率!J11 * 15) -> 20.1 | ... L11: =能力!L11 + (成長率!L11 * (15 - 能力!$M11)) + 転生後能力!L11 + (転生後成長率!L11 * 15) -> 31.8 | M11: 1 | N11: 20 | O11: =SUM(C11:L11) -> 168.5
B12: シュトレンク | C12: =能力!C12 + (成長率!C12 * (15 - 能力!$M12)) + 転生後能力!C12 + (転生後成長率!C12 * 15) -> 42.6 | D12: =能力!D12 + (成長率!D12 * (15 - 能力!$M12)) + 転生後能力!D12 + (転生後成長率!D12 * 15) -> 22 | E12: =能力!E12 + (成長率!E12 * (15 - 能力!$M12)) + 転生後能力!E12 + (転生後成長率!E12 * 15) -> 0.55 | F12: =能力!F12 + (成長率!F12 * (15 - 能力!$M12)) + 転生後能力!F12 + (転生後成長率!F12 * 15) -> 28.2 | G12: =能力!G12 + (成長率!G12 * (15 - 能力!$M12)) + 転生後能力!G12 + (転生後成長率!G12 * 15) -> 16.4 | H12: =能力!H12 + (成長率!H12 * (15 - 能力!$M12)) + 転生後能力!H12 + (転生後成長率!H12 * 15) -> 16.4 | I12: =能力!I12 + (成長率!I12 * (15 - 能力!$M12)) + 転生後能力!I12 + (転生後成長率!I12 * 15) -> 20.4 | J12: =能力!J12 + (成長率!J12 * (15 - 能力!$M12)) + 転生後能力!J12 + (転生後成長率!J12 * 15) -> 4.85 | ... L12: =能力!L12 + (成長率!L12 * (15 - 能力!$M12)) + 転生後能力!L12 + (転生後成長率!L12 * 15) -> 29.8 | M12: 4 | N12: 20 | O12: =SUM(C12:L12) -> 186.2
B13: リラ | C13: =能力!C13 + (成長率!C13 * (15 - 能力!$M13)) + 転生後能力!C13 + (転生後成長率!C13 * 15) -> 33 | D13: =能力!D13 + (成長率!D13 * (15 - 能力!$M13)) + 転生後能力!D13 + (転生後成長率!D13 * 15) -> 0 | E13: =能力!E13 + (成長率!E13 * (15 - 能力!$M13)) + 転生後能力!E13 + (転生後成長率!E13 * 15) -> 17.2 | F13: =能力!F13 + (成長率!F13 * (15 - 能力!$M13)) + 転生後能力!F13 + (転生後成長率!F13 * 15) -> 29.6 | G13: =能力!G13 + (成長率!G13 * (15 - 能力!$M13)) + 転生後能力!G13 + (転生後成長率!G13 * 15) -> 35.4 | H13: =能力!H13 + (成長率!H13 * (15 - 能力!$M13)) + 転生後能力!H13 + (転生後成長率!H13 * 15) -> 30.6 | I13: =能力!I13 + (成長率!I13 * (15 - 能力!$M13)) + 転生後能力!I13 + (転生後成長率!I13 * 15) -> 8.6 | J13: =能力!J13 + (成長率!J13 * (15 - 能力!$M13)) + 転生後能力!J13 + (転生後成長率!J13 * 15) -> 16.7 | ... L13: =能力!L13 + (成長率!L13 * (15 - 能力!$M13)) + 転生後能力!L13 + (転生後成長率!L13 * 15) -> 26.6 | M13: 2 | N13: 20 | O13: =SUM(C13:N13) -> 227.7
B14: ファルコン | C14: =能力!C14 + (成長率!C14 * (15 - 能力!$M14)) + 転生後能力!C14 + (転生後成長率!C14 * 15) -> 38.5 | D14: =能力!D14 + (成長率!D14 * (15 - 能力!$M14)) + 転生後能力!D14 + (転生後成長率!D14 * 15) -> 11.6 | E14: =能力!E14 + (成長率!E14 * (15 - 能力!$M14)) + 転生後能力!E14 + (転生後成長率!E14 * 15) -> 0.4 | F14: =能力!F14 + (成長率!F14 * (15 - 能力!$M14)) + 転生後能力!F14 + (転生後成長率!F14 * 15) -> 26.5 | G14: =能力!G14 + (成長率!G14 * (15 - 能力!$M14)) + 転生後能力!G14 + (転生後成長率!G14 * 15) -> 16.6 | H14: =能力!H14 + (成長率!H14 * (15 - 能力!$M14)) + 転生後能力!H14 + (転生後成長率!H14 * 15) -> 9.6 | I14: =能力!I14 + (成長率!I14 * (15 - 能力!$M14)) + 転生後能力!I14 + (転生後成長率!I14 * 15) -> 8.3 | J14: =能力!J14 + (成長率!J14 * (15 - 能力!$M14)) + 転生後能力!J14 + (転生後成長率!J14 * 15) -> 3.15 | ... L14: =能力!L14 + (成長率!L14 * (15 - 能力!$M14)) + 転生後能力!L14 + (転生後成長率!L14 * 15) -> 26.1 | M14: 7 | N14: 0 | O14: =SUM(C14:N14) -> 155.75
B15: ユーリ（ブレイド） | C15: =能力!C15 + (成長率!C15 * (15 - 能力!$M15)) + 転生後能力!C15 + (転生後成長率!C15 * 15) -> 46.8 | D15: =能力!D15 + (成長率!D15 * (15 - 能力!$M15)) + 転生後能力!D15 + (転生後成長率!D15 * 15) -> 15.8 | E15: =能力!E15 + (成長率!E15 * (15 - 能力!$M15)) + 転生後能力!E15 + (転生後成長率!E15 * 15) -> 8.8 | F15: =能力!F15 + (成長率!F15 * (15 - 能力!$M15)) + 転生後能力!F15 + (転生後成長率!F15 * 15) -> 18.6 | G15: =能力!G15 + (成長率!G15 * (15 - 能力!$M15)) + 転生後能力!G15 + (転生後成長率!G15 * 15) -> 20.6 | H15: =能力!H15 + (成長率!H15 * (15 - 能力!$M15)) + 転生後能力!H15 + (転生後成長率!H15 * 15) -> 18 | I15: =能力!I15 + (成長率!I15 * (15 - 能力!$M15)) + 転生後能力!I15 + (転生後成長率!I15 * 15) -> 14.8 | J15: =能力!J15 + (成長率!J15 * (15 - 能力!$M15)) + 転生後能力!J15 + (転生後成長率!J15 * 15) -> 7.8 | ... L15: =能力!L15 + (成長率!L15 * (15 - 能力!$M15)) + 転生後能力!L15 + (転生後成長率!L15 * 15) -> 23.7 | M15: 6 | N15: 20 | O15: =SUM(C15:N15) -> 205.9
B16: ユーリ（メイジ） | C16: =能力!C16 + (成長率!C16 * (15 - 能力!$M16)) + 転生後能力!C16 + (転生後成長率!C16 * 15) -> 46.8 | D16: =能力!D16 + (成長率!D16 * (15 - 能力!$M16)) + 転生後能力!D16 + (転生後成長率!D16 * 15) -> 10.8 | E16: =能力!E16 + (成長率!E16 * (15 - 能力!$M16)) + 転生後能力!E16 + (転生後成長率!E16 * 15) -> 13.8 | F16: =能力!F16 + (成長率!F16 * (15 - 能力!$M16)) + 転生後能力!F16 + (転生後成長率!F16 * 15) -> 19.6 | G16: =能力!G16 + (成長率!G16 * (15 - 能力!$M16)) + 転生後能力!G16 + (転生後成長率!G16 * 15) -> 19.6 | H16: =能力!H16 + (成長率!H16 * (15 - 能力!$M16)) + 転生後能力!H16 + (転生後成長率!H16 * 15) -> 18 | I16: =能力!I16 + (成長率!I16 * (15 - 能力!$M16)) + 転生後能力!I16 + (転生後成長率!I16 * 15) -> 8.8 | J16: =能力!J16 + (成長率!J16 * (15 - 能力!$M16)) + 転生後能力!J16 + (転生後成長率!J16 * 15) -> 13.8 | ... L16: =能力!L16 + (成長率!L16 * (15 - 能力!$M16)) + 転生後能力!L16 + (転生後成長率!L16 * 15) -> 23.7 | M16: 6 | N16: 20 | O16: =SUM(C16:N16) -> 205.9
B17: シラヌイ | C17: =能力!C17 + (成長率!C17 * (15 - 能力!$M17)) + 転生後能力!C17 + (転生後成長率!C17 * 15) -> 44.3 | D17: =能力!D17 + (成長率!D17 * (15 - 能力!$M17)) + 転生後能力!D17 + (転生後成長率!D17 * 15) -> 14.7 | E17: =能力!E17 + (成長率!E17 * (15 - 能力!$M17)) + 転生後能力!E17 + (転生後成長率!E17 * 15) -> 0 | F17: =能力!F17 + (成長率!F17 * (15 - 能力!$M17)) + 転生後能力!F17 + (転生後成長率!F17 * 15) -> 31.2 | G17: =能力!G17 + (成長率!G17 * (15 - 能力!$M17)) + 転生後能力!G17 + (転生後成長率!G17 * 15) -> 35.7 | H17: =能力!H17 + (成長率!H17 * (15 - 能力!$M17)) + 転生後能力!H17 + (転生後成長率!H17 * 15) -> 16.6 | I17: =能力!I17 + (成長率!I17 * (15 - 能力!$M17)) + 転生後能力!I17 + (転生後成長率!I17 * 15) -> 9.8 | J17: =能力!J17 + (成長率!J17 * (15 - 能力!$M17)) + 転生後能力!J17 + (転生後成長率!J17 * 15) -> 1.4 | ... L17: =能力!L17 + (成長率!L17 * (15 - 能力!$M17)) + 転生後能力!L17 + (転生後成長率!L17 * 15) -> 25.9 | M17: 6 | N17: 20 | O17: =SUM(C17:N17) -> 211.6
B21: ルメンテ | C21: 47.2 | D21: 16.2 | E21: 0 | F21: 16.2 | G21: 14.2 | H21: 7.8 | I21: 15.2 | J21: 1.2 | K21: 4 | L21: 23.4
B22: レジェ | C22: 45.6 | D22: 17.7 | E22: 0 | F22: 26.4 | G22: 27.4 | H22: 31.2 | I22: 11.3 | J22: 4.03 | K22: 5 | L22: 24.4
B23: レガート（パラディン） | C23: 45.2 | D23: 19.4 | E23: 3.6 | F23: 20 | G23: 20 | H23: 16.4 | I23: 11.2 | J23: 7.6 | K23: 7 | L23: 20.4
B24: レガート (Uナイト) | C24: 46.2 | D24: 17.4 | E24: 3.6 | F24: 21 | G24: 20 | H24: 16.4 | I24: 14.2 | J24: 7.6 | K24: 7 | L24: 22.4
B25: アグリ | C25: 59.3 | D25: 22.5 | E25: 0 | F25: 20.5 | G25: 18.8 | H25: 14.8 | I25: 13.1 | J25: 0 | K25: 4 | L25: 21.2
B26: モレンド | C26: 33.4 | D26: 9.8 | E26: 0 | F26: 15.6 | G26: 35.1 | H26: 23.4 | I26: 5.9 | J26: 1.45 | K26: 6.45 | L26: 23.4
B27: トーン (賢者) | C27: 37.4 | D27: 0 | E27: 10.8 | F27: 16.6 | G27: 17.6 | H27: 28.3 | I27: 4.9 | J27: 15.7 | K27: 4 | L27: 31.2
B28: トーン (学者) | C28: 37.4 | D28: 0 | E28: 8.8 | F28: 16.6 | G28: 15.6 | H28: 28.3 | I28: 3.9 | J28: 18.7 | K28: 4 | L28: 33.2
B29: シュトレンク | C29: 42.6 | D29: 22 | E29: 0 | F29: 28.2 | G29: 16.4 | H29: 14.4 | I29: 20.4 | J29: 4.3 | K29: 4 | L29: 30.8
B30: リラ | C30: 32 | D30: 0 | E30: 17.2 | F30: 29.6 | G30: 37.4 | H30: 30.6 | I30: 8.6 | J30: 16.4 | K30: 6 | L30: 28.6
B31: ファルコン | C31: 38.5 | D31: 11.6 | E31: 0 | F31: 24.5 | G31: 16.6 | H31: 9.6 | I31: 8.3 | J31: 4.15 | K31: 7 | L31: 26.1
B32: ユーリ（ブレイド） | C32: 46.8 | D32: 15.7 | E32: 9.7 | F32: 20.6 | G32: 19.6 | H32: 18 | I32: 15.7 | J32: 8.7 | K32: 4 | L32: 21
B33: ユーリ（メイジ） | C33: 46.8 | D33: 10.7 | E33: 14.7 | F33: 18.6 | G33: 21.6 | H33: 18 | I33: 9.7 | J33: 14.7 | K33: 4 | L33: 21

Sheet 全部
B1: Gaining Fate ユニット 期待値一覧
B3: 能力 | R3: 転生後能力
C4: HP | D4: 力 | E4: 魔力 | F4: 技 | G4: 速さ | H4: 幸運 | I4: 守備力 | J4: 魔防力 | K4: 移動力 | L4: 熟練度 | M4: レベル | N4: 転生 | O4: 計（初期値） | S4: HP | T4: 力 | U4: 魔力 | V4: 技 | W4: 速さ | X4: 幸運 | Y4: 守備力 | Z4: 魔防力 | AA4: 移動力 | AB4: 熟練度 | AC4: レベル | AD4: 転生 | AE4: 計（初期値）
B5: ルメンテ | C5: 28 | D5: 9 | E5: 0 | F5: 9 | G5: 7 | H5: 3 | I5: 8 | J5: 0 | K5: 4 | L5: 9 | M5: 6 | N5: 0 | O5: =SUM(C5:L5) -> 77 | R5: ルメンテ | S5: 0 | T5: 0 | U5: 0 | V5: 0 | W5: 0 | X5: 0 | Y5: 0 | Z5: 0 | AA5: 0 | AB5: 0 | AC5: 6 | AD5: 0 | AE5: =SUM(S5:AB5) -> 0
B6: レジェ | C6: 13 | D6: 4 | E6: 0 | F6: 4 | G6: 5 | H6: 6 | I6: 2 | J6: 0 | K6: 4 | L6: 2 | M6: 1 | N6: 20 | O6: =SUM(C6:L6) -> 40 | R6: レジェ | S6: 2 | T6: 2 | U6: 0 | V6: 2 | W6: 2 | X6: 2 | Y6: 2 | Z6: 2 | AA6: 0 | AB6: 2 | AC6: 1 | AD6: 20 | AE6: =SUM(S6:AB6) -> 16
B7: レガート | C7: 25 | D7: 7 | E7: 1 | F7: 5 | G7: 5 | H7: 5 | I7: 6 | J7: 2 | K7: 6 | L7: 7 | M7: 4 | N7: 20 | O7: =SUM(C7:L7) -> 69 | R7: レガート | S7: 2 | T7: 2 | U7: 0 | V7: 2 | W7: 2 | X7: 1 | Y7: 0 | Z7: 3 | AA7: 1 | AB7: 3 | AC7: 4 | AD7: 20 | AE7: =SUM(S7:AB7) -> 16
B8: アグリ | C8: 28 | D8: 7 | E8: 0 | F8: 4 | G8: 6 | H8: 4 | I8: 5 | J8: 0 | K8: 4 | L8: 5 | M8: 3 | N8: 20 | O8: =SUM(C8:L8) -> 63 | R8: アグリ | S8: 7 | T8: 2 | U8: 0 | V8: 0 | W8: 2 | X8: 0 | Y8: 0 | Z8: 0 | AA8: 0 | AB8: 0 | AC8: 3 | AD8: 20 | AE8: =SUM(S8:AB8) -> 11
B9: モレンド | C9: 16 | D9: 4 | E9: 0 | F9: 4 | G9: 9 | H9: 6 | I9: 3 | J9: 0 | K9: 5 | L9: 6 | M9: 1 | N9: 0 | O9: =SUM(C9:L9) -> 53 | R9: モレンド | S9: 0 | T9: 0 | U9: 0 | V9: 0 | W9: 0 | X9: 0 | Y9: 0 | Z9: 0 | AA9: 0 | AB9: 0 | AC9: 1 | AD9: 0 | AE9: =SUM(S9:AB9) -> 0
B10: トーン | C10: 17 | D10: 0 | E10: 2 | F10: 3 | G10: 4 | H10: 8 | I10: 1 | J10: 5 | K10: 4 | L10: 5 | M10: 1 | N10: 20 | O10: =SUM(C10:L10) -> 49 | R10: トーン | S10: 2 | T10: 0 | U10: 3 | V10: 2 | W10: 2 | X10: 0 | Y10: 1 | Z10: 2 | AA10: 0 | AB10: 4 | AC10: 1 | AD10: 20 | AE10: =SUM(S10:AB10) -> 16
B11: シュトレンク | C11: 25 | D11: 7 | E11: 0 | F11: 8 | G11: 6 | H11: 4 | I11: 7 | J11: 0 | K11: 4 | L11: 7 | M11: 4 | N11: 20 | O11: =SUM(C11:L11) -> 68 | R11: シュトレンク | S11: 2 | T11: 2 | U11: 0 | V11: 2 | W11: 0 | X11: 0 | Y11: 3 | Z11: 3 | AA11: 0 | AB11: 3 | AC11: 4 | AD11: 20 | AE11: =SUM(S11:AB11) -> 15
B12: リラ | C12: 18 | D12: 0 | E12: 4 | F12: 7 | G12: 10 | H12: 8 | I12: 2 | J12: 6 | K12: 5 | L12: 6 | M12: 2 | N12: 20 | O12: =SUM(C12:L12) -> 66 | R12: リラ | S12: 0 | T12: 0 | U12: 2 | V12: 5 | W12: 5 | X12: 0 | Y12: 1 | Z12: 2 | AA12: 1 | AB12: 5 | AC12: 2 | AD12: 20 | AE12: =SUM(S12:AB12) -> 21
B13: ファルコン | C13: 25 | D13: 6 | E13: 0 | F13: 10 | G13: 10 | H13: 5 | I13: 5 | J13: 0 | K13: 6 | L13: 8 | M13: 3 | N13: 0 | O13: =SUM(C13:L13) -> 75 | R13: ファルコン | S13: 0 | T13: 0 | U13: 0 | V13: 0 | W13: 0 | X13: 0 | Y13: 0 | Z13: 0 | AA13: 0 | AB13: 0 | AC13: 3 | AD13: 0 | AE13: =SUM(S13:AB13) -> 0
B14: ユーリ | C14: 27 | D14: 4 | E14: 3 | F14: 8 | G14: 9 | H14: 5 | I14: 4 | J14: 3 | K14: 4 | L14: 7 | M14: 6 | N14: 20 | O14: =SUM(C14:L14) -> 74 | R14: ユーリ | S14: 0 | T14: 2 | U14: 2 | V14: 0 | W14: 0 | X14: 0 | Y14: 2 | Z14: 2 | AA14: 0 | AB14: 0 | AC14: 6 | AD14: 20 | AE14: =SUM(S14:AB14) -> 8
B17: 成長率 | R17: 転生後成長率
C18: HP | D18: 力 | E18: 魔力 | F18: 技 | G18: 速さ | H18: 幸運 | I18: 守備力 | J18: 魔防力 | K18: 移動力 | L18: 熟練度 | M18: レベル | N18: 転生 | O18: 計 | S18: HP | T18: 力 | U18: 魔力 | V18: 技 | W18: 速さ | X18: 幸運 | Y18: 守備力 | Z18: 魔防力 | AA18: 移動力 | AB18: 熟練度 | AC18: レベル | AD18: 転生 | AE18: 計
B19: ルメンテ | C19: 0.8 | D19: 0.5 | E19: 0 | F19: 0.3 | G19: 0.3 | H19: 0.2 | I19: 0.5 | J19: 0.05 | K19: 0 | L19: 0.6 | M19: 6 | N19: 0 | O19: =SUM(C19:L19) -> 3.25 | R19: ルメンテ | S19: 0 | T19: 0 | U19: 0 | V19: 0 | W19: 0 | X19: 0 | Y19: 0 | Z19: 0 | AA19: 0 | AB19: 0 | AC19: 6 | AD19: 0 | AE19: =SUM(S19:AB19) -> 0
B20: レジェ | C20: 0.6 | D20: 0.3 | E20: 0 | F20: 0.5 | G20: 0.5 | H20: 0.8 | I20: 0.2 | J20: 0.05 | K20: 0 | L20: 0.6 | M20: 1 | N20: 20 | O20: =SUM(C20:L20) -> 3.55 | R20: レジェ | S20: 0.8 | T20: 0.6 | U20: 0 | V20: 0.8 | W20: 0.8 | X20: 0.8 | Y20: 0.3 | Z20: 0.05 | AA20: 0 | AB20: 0.9 | AC20: 1 | AD20: 20 | AE20: =SUM(S20:AB20) -> 5.05
B21: レガート | C21: 0.7 | D21: 0.4 | E21: 0.1 | F21: 0.5 | G21: 0.5 | H21: 0.4 | I21: 0.2 | J21: 0.05 | K21: 0 | L21: 0.4 | M21: 4 | N21: 20 | O21: =SUM(C21:L21) -> 3.25 | R21: レガート | S21: 0.7 | T21: 0.4 | U21: 0.1 | V21: 0.5 | W21: 0.5 | X21: 0.4 | Y21: 0.2 | Z21: 0.05 | AA21: 0 | AB21: 0.4 | AC21: 4 | AD21: 20 | AE21: =SUM(S21:AB21) -> 3.25
B22: アグリ | C22: 0.8 | D22: 0.6 | E22: 0 | F22: 0.6 | G22: 0.5 | H22: 0.4 | I22: 0.3 | J22: 0 | K22: 0 | L22: 0.6 | M22: 3 | N22: 20 | O22: =SUM(C22:L22) -> 3.8 | R22: アグリ | S22: 0.8 | T22: 0.6 | U22: 0 | V22: 0.6 | W22: 0.5 | X22: 0.4 | Y22: 0.3 | Z22: 0 | AA22: 0 | AB22: 0.6 | AC22: 3 | AD22: 20 | AE22: =SUM(S22:AB22) -> 3.8
B23: モレンド | C23: 0.6 | D23: 0.3 | E23: 0 | F23: 0.6 | G23: 0.8 | H23: 0.6 | I23: 0.1 | J23: 0.05 | K23: 0.05 | L23: 0.8 | M23: 1 | N23: 0 | O23: =SUM(C23:L23) -> 3.9 | R23: モレンド | S23: 0 | T23: 0 | U23: 0 | V23: 0 | W23: 0 | X23: 0 | Y23: 0 | Z23: 0 | AA23: 0 | AB23: 0 | AC23: 1 | AD23: 0 | AE23: =SUM(S23:AB23) -> 0
B24: トーン | C24: 0.6 | D24: 0 | E24: 0.2 | F24: 0.4 | G24: 0.4 | H24: 0.7 | I24: 0.1 | J24: 0.3 | K24: 0 | L24: 0.8 | M24: 1 | N24: 20 | O24: =SUM(C24:L24) -> 3.5 | R24: トーン | S24: 0.6 | T24: 0 | U24: 0.2 | V24: 0.4 | W24: 0.4 | X24: 0.7 | Y24: 0.1 | Z24: 0.3 | AA24: 0 | AB24: 0.8 | AC24: 1 | AD24: 20 | AE24: =SUM(S24:AB24) -> 3.5
B25: シュトレンク | C25: 0.6 | D25: 0.5 | E25: 0 | F25: 0.7 | G25: 0.4 | H25: 0.4 | I25: 0.4 | J25: 0.05 | K25: 0 | L25: 0.8 | M25: 4 | N25: 20 | O25: =SUM(C25:L25) -> 3.85 | R25: シュトレンク | S25: 0.6 | T25: 0.5 | U25: 0 | V25: 0.7 | W25: 0.4 | X25: 0.4 | Y25: 0.4 | Z25: 0 | AA25: 0 | AB25: 0.8 | AC25: 4 | AD25: 20 | AE25: =SUM(S25:AB25) -> 3.8
B26: リラ | C26: 0.5 | D26: 0 | E26: 0.4 | F26: 0.7 | G26: 0.8 | H26: 0.6 | I26: 0.2 | J26: 0.3 | K26: 0 | L26: 0.7 | M26: 2 | N26: 20 | O26: =SUM(C26:L26) -> 4.2 | R26: リラ | S26: 0.5 | T26: 0 | U26: 0.4 | V26: 0.7 | W26: 0.8 | X26: 0.6 | Y26: 0.2 | Z26: 0.3 | AA26: 0 | AB26: 0.7 | AC26: 2 | AD26: 20 | AE26: =SUM(S26:AB26) -> 4.2
B27: ファルコン | C27: 0.5 | D27: 0.3 | E27: 0 | F27: 0.8 | G27: 0.5 | H27: 0.4 | I27: 0.2 | J27: 0 | K27: 0 | L27: 0.7 | M27: 3 | N27: 0 | O27: =SUM(C27:L27) -> 3.4 | R27: ファルコン | S27: 0 | T27: 0 | U27: 0 | V27: 0 | W27: 0 | X27: 0 | Y27: 0 | Z27: 0 | AA27: 0 | AB27: 0 | AC27: 3 | AD27: 0 | AE27: =SUM(S27:AB27) -> 0
B28: ユーリ | D28: 0.3 | E28: 0.3 | F28: 0.6 | G28: 0.7 | H28: 0.5 | I28: 0.2 | J28: 0.2 | K28: 0 | L28: 0.5 | M28: 6 | N28: 20 | O28: =SUM(C28:L28) -> 3.3 | R28: ユーリ | S28: 0.7 | T28: 0.3 | U28: 0.3 | V28: 0.6 | W28: 0.7 | X28: 0.5 | Y28: 0.2 | Z28: 0.2 | AA28: 0 | AB28: 0.5 | AC28: 6 | AD28: 20 | AE28: =SUM(S28:AB28) -> 4
B31: 期待値
C32: HP | D32: 力 | E32: 魔力 | F32: 技 | G32: 速さ | H32: 幸運 | I32: 守備力 | J32: 魔防力 | K32: 移動力 | L32: 熟練度 | M32: レベル | N32: 転生 | O32: 計（期待値）
B33: ルメンテ | C33: 39.2 | D33: 16 | E33: 0 | F33: 13.2 | G33: 11.2 | H33: 5.8 | I33: 15 | J33: 0.7 | K33: 4 | L33: 17.4 | M33: 6 | N33: 0 | O33: 122.5
B34: レジェ | C34: 42.4 | D34: 23.7 | E34: 0 | F34: 31.5 | G34: 32.5 | H34: 39.2 | I34: 13.8 | J34: 3.95 | K34: 4 | L34: 33.4 | M34: 1 | N34: 20 | O34: 224.45 | R34: 28 | S34: 7 | T34: 0 | U34: 4 | V34: 6 | W34: 4 | X34: 5 | Y34: 0 | Z34: 4 | AA34: 5
B35: レガート | C35: 52.2 | D35: 23.4 | E35: 4.6 | F35: 25 | G35: 25 | H35: 20.4 | I35: 13.2 | J35: 6.8 | K35: 7 | L35: 24.4 | M35: 4 | N35: 20 | O35: 202 | R35: 0.8 | S35: 0.6 | T35: 0 | U35: 0.6 | V35: 0.5 | W35: 0.4 | X35: 0.3 | Y35: 0 | Z35: 0 | AA35: 0.6
B36: アグリ | C36: 64.6 | D36: 31.2 | E36: 0 | F36: 26.2 | G36: 26.5 | H36: 18.8 | I36: 16.1 | J36: 0 | K36: 4 | L36: 27.2 | M36: 3 | N36: 20 | O36: 214.6 | R36: 7 | S36: 2 | T36: 0 | U36: 0 | V36: 2 | W36: 0 | X36: 0 | Y36: 0 | Z36: 0 | AA36: 0
B37: モレンド | C37: 27.4 | D37: 9.7 | E37: 0 | F37: 15.4 | G37: 24.2 | H37: 17.4 | I37: 4.9 | J37: 0.95 | K37: 5.95 | L37: 21.2 | M37: 1 | N37: 0 | O37: 127.1 | R37: 0.8 | S37: 0.6 | T37: 0 | U37: 0.6 | V37: 0.5 | W37: 0.4 | X37: 0.3 | Y37: 0 | Z37: 0 | AA37: 0.6
B38: トーン | C38: 42.4 | D38: 0 | E38: 12.8 | F38: 20.6 | G38: 21.6 | H38: 35.3 | I38: 5.9 | J38: 18.7 | K38: 4 | L38: 40.2 | M38: 1 | N38: 20 | O38: 201.5 | R38: 64.6 | S38: 31.2 | T38: 0 | U38: 26.2 | V38: 26.5 | W38: 18.8 | X38: 16.1 | Y38: 0 | Z38: 4 | AA38: 27.2
B39: シュトレンク | C39: 48.6 | D39: 27 | E39: 0 | F39: 35.2 | G39: 20.4 | H39: 18.4 | I39: 24.4 | J39: 3.8 | K39: 4 | L39: 38.8 | M39: 4 | N39: 20 | O39: 220.6
B40: リラ | C40: 37 | D40: 0 | E40: 21.2 | F40: 38.6 | G40: 45.4 | H40: 30.8 | I40: 10.6 | J40: 19.4 | K40: 6 | L40: 37.6 | M40: 2 | N40: 20 | O40: 268.6
B41: ファルコン | C41: 33.5 | D41: 11.1 | E41: 0 | F41: 23.6 | G41: 18.5 | H41: 11.8 | I41: 8.4 | J41: 0 | K41: 6 | L41: 19.9 | M41: 3 | N41: 0 | O41: 135.8
B42: ユーリ | C42: 50.8 | D42: 16.2 | E42: 15.2 | F42: 28.4 | G42: 32.8 | H42: 22 | I42: 12.8 | J42: 11.8 | K42: 4 | L42: 24 | M42: 6 | N42: 20 | O42: 244

Sheet CC
C2: HP | D2: 力 | E2: 魔力 | F2: 技 | G2: 速さ | H2: 幸運 | I2: 守備力 | J2: 魔防力 | K2: 移動力 | L2: 熟練度 | M2: 合計 | N2: スキル | O2: 剣 | P2: 槍 | Q2: 斧 | R2: 弓 | S2: 杖 | T2: 火 | U2: 雷 | V2: 氷 | W2: 格
B3: ソードマスター | C3: 1 | D3: 2 | E3: 0 | F3: 3 | G3: 4 | H3: 2 | I3: 1 | J3: 1 | K3: 0 | L3: 0 | M3: =SUM(C3:L3) -> 14 | N3: 追撃 | O3: 〇
B4: 傭兵 | C4: 4 | D4: 2 | E4: 0 | F4: 2 | G4: 2 | H4: 0 | I4: 2 | J4: 2 | K4: 0 | L4: 0 | M4: =SUM(C4:L4) -> 14 | N4: 不屈 | O4: 〇
B5: ガーディアン | C5: 2 | D5: 2 | E5: 0 | F5: 2 | G5: 1 | H5: 1 | I5: 3 | J5: 3 | K5: 0 | L5: 0 | M5: =SUM(C5:L5) -> 14 | N5: 先制 | P5: 〇
B6: バーサーカー | C6: 7 | D6: 3 | E6: 0 | F6: 1 | G6: 2 | H6: 0 | I6: 1 | J6: 0 | K6: 0 | L6: 0 | M6: =SUM(C6:L6) -> 14 | N6: 追撃 | Q6: 〇 | W6: 〇
B7: パラディン | C7: 2 | D7: 2 | E7: 0 | F7: 2 | G7: 2 | H7: 1 | I7: 2 | J7: 2 | K7: 2 | L7: 0 | M7: =SUM(C7:L7) -> 15 | N7: 再移動 追撃 | P7: 〇
B8: ウェポンナイト | C8: 3 | D8: 1 | E8: 0 | F8: 2 | G8: 1 | H8: 1 | I8: 3 | J8: 2 | K8: 2 | L8: 0 | M8: =SUM(C8:L8) -> 15 | N8: 再移動 | O8: 〇 | P8: 〇 | Q8: 〇
B9: しさい | C9: 2 | D9: 0 | E9: 4 | F9: 2 | G9: 0 | H9: 3 | I9: 1 | J9: 2 | K9: 0 | L9: 0 | M9: =SUM(C9:L9) -> 14 | N9: 祈り | S9: 〇 | T9: 〇 | U9: 〇 | V9: 〇
B10: がくしゃ | C10: 3 | D10: 0 | E10: 1 | F10: 2 | G10: 0 | H10: 1 | I10: 2 | J10: 5 | K10: 0 | L10: 0 | M10: =SUM(C10:L10) -> 14 | N10: 知恵 | S10: 〇 | T10: 〇 | U10: 〇 | V10: 〇
B11: ぐんし | C11: 2 | D11: 0 | E11: 0 | F11: 0 | G11: 2 | H11: 5 | I11: 2 | J11: 2 | K11: 1 | L11: 0 | M11: =SUM(C11:L11) -> 14 | N11: 知恵 連携 | W11: 〇
B12: グリフォンナイト | C12: 1 | D12: 1 | E12: 1 | F12: 2 | G12: 3 | H12: 1 | I12: 1 | J12: 3 | K12: 2 | L12: 0 | M12: =SUM(C12:L12) -> 15 | N12: 再移動 みかわし
B13: ドラゴンナイト | C13: 3 | D13: 3 | E13: 0 | F13: 1 | G13: 3 | H13: 0 | I13: 3 | J13: 0 | K13: 2 | L13: 0 | M13: =SUM(C13:L13) -> 15 | N13: 再移動 連続 | P13: 〇 | Q13: 〇
B14: ホースメン | C14: 2 | D14: 1 | E14: 0 | F14: 5 | G14: 2 | H14: 0 | I14: 1 | J14: 2 | K14: 2 | L14: 0 | M14: =SUM(C14:L14) -> 15 | N14: 必中 | R14: 〇
B15: スナイパー | C15: 2 | D15: 2 | E15: 0 | F15: 3 | G15: 2 | H15: 1 | I15: 2 | J15: 2 | K15: 0 | L15: 0 | M15: =SUM(C15:L15) -> 14 | N15: 必殺 | R15: 〇
B16: ジェネラル | C16: 3 | D16: 2 | E16: 0 | F16: 1 | G16: 0 | H16: 1 | I16: 5 | J16: 2 | K16: 0 | L16: 0 | M16: =SUM(C16:L16) -> 14 | N16: 暗黒 | P16: 〇 | Q16: 〇 | R16: 〇
B17: 魔道アーマー | C17: 3 | D17: 0 | E17: 2 | F17: 1 | G17: 0 | H17: 0 | I17: 3 | J17: 5 | K17: 0 | L17: 0 | M17: =SUM(C17:L17) -> 14 | N17: 暗黒 | Q17: 〇 | T17: 〇 | U17: 〇 | V17: 〇
B18: ブレイド | C18: 3 | D18: 3 | E18: 1 | F18: 1 | G18: 2 | H18: 1 | I18: 3 | J18: 0 | K18: 0 | L18: 0 | M18: =SUM(C18:L18) -> 14 | N18: 追撃 | O18: 〇 | T18: 〇 | U18: 〇 | V18: 〇
B19: メイジ | C19: 3 | D19: 1 | E19: 3 | F19: 2 | G19: 1 | H19: 1 | I19: 0 | J19: 3 | K19: 0 | L19: 0 | M19: =SUM(C19:L19) -> 14 | N19: 節約 | O19: 〇 | S19: 〇 | T19: 〇 | U19: 〇 | V19: 〇
B20: しはんだい | C20: 0 | D20: 1 | E20: 1 | F20: 3 | G20: 4 | H20: 3 | I20: 1 | J20: 1 | K20: 0 | L20: 0 | M20: =SUM(C20:L20) -> 14 | N20: 連続 | O20: 〇 | S20: 〇 | T20: 〇 | U20: 〇 | V20: 〇
B22: ルメンテ | C22: 30 | D22: 7 | E22: 0 | F22: 6 | G22: 4 | H22: 0 | I22: 13 | J22: 0 | K22: 4 | L22: 8
B23: ソードマスター | C23: =C$22-C3 -> 29 | D23: =D$22-D3 -> 5 | E23: =E$22-E3 -> 0 | F23: =F$22-F3 -> 3 | G23: =G$22-G3 -> 0 | H23: =H$22-H3 -> -2 | I23: =I$22-I3 -> 12 | J23: =J$22-J3 -> -1 | ... L23: =L$22-L3 -> 8
B24: 傭兵 | C24: =C$22-C4 -> 26 | D24: =D$22-D4 -> 5 | E24: =E$22-E4 -> 0 | F24: =F$22-F4 -> 4 | G24: =G$22-G4 -> 2 | H24: =H$22-H4 -> 0 | I24: =I$22-I4 -> 11 | J24: =J$22-J4 -> -2 | ... L24: =L$22-L4 -> 8
B25: ガーディアン | C25: =C$22-C5 -> 28 | D25: =D$22-D5 -> 5 | E25: =E$22-E5 -> 0 | F25: =F$22-F5 -> 4 | G25: =G$22-G5 -> 3 | H25: =H$22-H5 -> -1 | I25: =I$22-I5 -> 10 | J25: =J$22-J5 -> -3 | ... L25: =L$22-L5 -> 8
B26: バーサーカー | C26: =C$22-C6 -> 23 | D26: =D$22-D6 -> 4 | E26: =E$22-E6 -> 0 | F26: =F$22-F6 -> 5 | G26: =G$22-G6 -> 2 | H26: =H$22-H6 -> 0 | I26: =I$22-I6 -> 12 | J26: =J$22-J6 -> 0 | ... L26: =L$22-L6 -> 8
B27: パラディン | C27: =C$22-C7 -> 28 | D27: =D$22-D7 -> 5 | E27: =E$22-E7 -> 0 | F27: =F$22-F7 -> 4 | G27: =G$22-G7 -> 2 | H27: =H$22-H7 -> -1 | I27: =I$22-I7 -> 11 | J27: =J$22-J7 -> -2 | ... L27: =L$22-L7 -> 8
B28: ウェポンナイト | C28: =C$22-C8 -> 27 | D28: =D$22-D8 -> 6 | E28: =E$22-E8 -> 0 | F28: =F$22-F8 -> 4 | G28: =G$22-G8 -> 3 | H28: =H$22-H8 -> -1 | I28: =I$22-I8 -> 10 | J28: =J$22-J8 -> -2 | ... L28: =L$22-L8 -> 8
B29: しさい | C29: =C$22-C9 -> 28 | D29: =D$22-D9 -> 7 | E29: =E$22-E9 -> -4 | F29: =F$22-F9 -> 4 | G29: =G$22-G9 -> 4 | H29: =H$22-H9 -> -3 | I29: =I$22-I9 -> 12 | J29: =J$22-J9 -> -2 | ... L29: =L$22-L9 -> 8
B30: がくしゃ | C30: =C$22-C10 -> 27 | D30: =D$22-D10 -> 7 | E30: =E$22-E10 -> -1 | F30: =F$22-F10 -> 4 | G30: =G$22-G10 -> 4 | H30: =H$22-H10 -> -1 | I30: =I$22-I10 -> 11 | J30: =J$22-J10 -> -5 | ... L30: =L$22-L10 -> 8
B31: ぐんし | C31: =C$22-C11 -> 28 | D31: =D$22-D11 -> 7 | E31: =E$22-E11 -> 0 | F31: =F$22-F11 -> 6 | G31: =G$22-G11 -> 2 | H31: =H$22-H11 -> -5 | I31: =I$22-I11 -> 11 | J31: =J$22-J11 -> -2 | ... L31: =L$22-L11 -> 8
B32: ドラゴンナイト | C32: =C$22-C13 -> 27 | D32: =D$22-D13 -> 4 | E32: =E$22-E13 -> 0 | F32: =F$22-F13 -> 5 | G32: =G$22-G13 -> 1 | H32: =H$22-H13 -> 0 | I32: =I$22-I13 -> 10 | J32: =J$22-J13 -> 0 | ... L32: =L$22-L13 -> 8
B33: ホースメン | C33: =C$22-C14 -> 28 | D33: =D$22-D14 -> 6 | E33: =E$22-E14 -> 0 | F33: =F$22-F14 -> 1 | G33: =G$22-G14 -> 2 | H33: =H$22-H14 -> 0 | I33: =I$22-I14 -> 12 | J33: =J$22-J14 -> -2 | ... L33: =L$22-L14 -> 8
B34: スナイパー | C34: =C$22-C15 -> 28 | D34: =D$22-D15 -> 5 | E34: =E$22-E15 -> 0 | F34: =F$22-F15 -> 3 | G34: =G$22-G15 -> 2 | H34: =H$22-H15 -> -1 | I34: =I$22-I15 -> 11 | J34: =J$22-J15 -> -2 | ... L34: =L$22-L15 -> 8
B35: ジェネラル | C35: =C$22-C16 -> 27 | D35: =D$22-D16 -> 5 | E35: =E$22-E16 -> 0 | F35: =F$22-F16 -> 5 | G35: =G$22-G16 -> 4 | H35: =H$22-H16 -> -1 | I35: =I$22-I16 -> 8 | J35: =J$22-J16 -> -2 | ... L35: =L$22-L16 -> 8
B36: ブレイド | C36: =C$22-C18 -> 27 | D36: =D$22-D18 -> 4 | E36: =E$22-E18 -> -1 | F36: =F$22-F18 -> 5 | G36: =G$22-G18 -> 2 | H36: =H$22-H18 -> -1 | I36: =I$22-I18 -> 10 | J36: =J$22-J18 -> 0 | ... L36: =L$22-L18 -> 8
B37: メイジ | C37: =C$22-C19 -> 27 | D37: =D$22-D19 -> 6 | E37: =E$22-E19 -> -3 | F37: =F$22-F19 -> 4 | G37: =G$22-G19 -> 3 | H37: =H$22-H19 -> -1 | I37: =I$22-I19 -> 13 | J37: =J$22-J19 -> -3 | ... L37: =L$22-L19 -> 8

Sheet Sheet1
C2: 剣 | D2: 槍 | E2: 斧 | F2: 格闘 | G2: 弓 | H2: 火 | I2: 雷 | J2: 氷 | K2: 杖
B3: 傭兵 | C3: S
B4: アサルト（レジェ） | C4: C
B5: アサルト（ギル） | C5: S
B6: アサシン | C6: S | F6: B
B7: 盗賊 | C7: C
B8: ソシアルナイト | D8: B
B9: 魔道ナイト | H9: B | I9: B | J9: A
B10: パラディン | D10: S
B11: ウェポンナイト | C11: B | D11: A | E11: B
B12: 戦士 | E12: B | F12: B
B13: バーサーカー | E13: A | F13: A
B14: シスター | K14: B
B15: 賢者 | H15: S | I15: A | J15: B | K15: A
B16: 学者 | H16: B | I16: C | J16: C | K16: S
B17: 衛兵 | D17: B
B18: ガーディアン | D18: S
B19: ソードアーマー | C19: B
B20: ランスアーマー | D20: B
B21: アクスアーマー | E21: B
B22: ジェネラル | D22: A | E22: A
B23: 魔女 | H23: S
B24: ウィッチ | H24: S | K24: B
B25: 蛮族 | E25: B
B26: アーチャー | G26: B
B27: スナイパー | G27: S
B28: ベア | F28: C
B29: コング | F29: B
B30: 剣士 | C30: B
B31: 剣豪 | C31: S
B32: 魔導士 | H32: B | I32: B | J32: B
B33: シューター | G33: B
B34: ハンター | G34: B
B35: ホースメン | G35: A
B36: 魔剣士 | C36: B | H36: B | I36: B | J36: B
B37: メイジ | C37: B | H37: B | J37: B | K37: B
B38: ブレイド | C38: A | H38: A | I38: C
B39: ビーストナイト | C39: B | D39: B
B40: グリフォンナイト | C40: A | D40: A
B41: 忍者 | C41: A | F41: B
...
